<sdf version='1.6'>
  <world name='default'>
    <gui fullscreen='0'>
      <plugin name='keyboard' filename='libKeyboardGUIPlugin.so'/>
      <camera name='user_camera'>
        <pose frame=''>8.21944 -474.434 97.2578 -0 0.555999 1.418</pose>
        <view_controller>orbit</view_controller>
        <projection_type>perspective</projection_type>
      </camera>
    </gui>
    <light name='sun' type='directional'>
      <cast_shadows>1</cast_shadows>
      <pose frame=''>0 0 10 0 -0 0</pose>
      <diffuse>0.8 0.8 0.8 1</diffuse>
      <specular>0.2 0.2 0.2 1</specular>
      <attenuation>
        <range>1000</range>
        <constant>0.9</constant>
        <linear>0.01</linear>
        <quadratic>0.001</quadratic>
      </attenuation>
      <direction>-0.5 0.1 -0.9</direction>
    </light>
    <model name='cafe'>
      <static>1</static>
      <link name='link'>
        <collision name='collision'>
          <geometry>
            <mesh>
              <scale>0.254 0.254 0.254</scale>
              <uri>model://mcity/meshes/mcity.obj</uri>
            </mesh>
          </geometry>
          <max_contacts>10</max_contacts>
          <surface>
            <contact>
              <ode/>
            </contact>
            <bounce/>
            <friction>
              <torsional>
                <ode/>
              </torsional>
              <ode/>
            </friction>
          </surface>
        </collision>
        <visual name='visual'>
          <geometry>
            <mesh>
              <scale>0.254 0.254 0.254</scale>
              <uri>model://mcity/meshes/mcity.obj</uri>
            </mesh>
          </geometry>
        </visual>
        <self_collide>0</self_collide>
        <enable_wind>0</enable_wind>
        <kinematic>0</kinematic>
      </link>
    </model>
    <gravity>0 0 -9.8</gravity>
    <magnetic_field>6e-06 2.3e-05 -4.2e-05</magnetic_field>
    <atmosphere type='adiabatic'/>
    <physics name='default_physics' default='0' type='ode'>
      <max_step_size>0.001</max_step_size>
      <real_time_factor>1</real_time_factor>
      <real_time_update_rate>1000</real_time_update_rate>
    </physics>
    <scene>
      <ambient>0.4 0.4 0.4 1</ambient>
      <background>0.7 0.7 0.7 1</background>
      <sky/>
      <shadows>1</shadows>
    </scene>
    <audio>
      <device>default</device>
    </audio>
    <wind/>
    <spherical_coordinates>
      <surface_model>EARTH_WGS84</surface_model>
      <latitude_deg>0</latitude_deg>
      <longitude_deg>0</longitude_deg>
      <elevation>0</elevation>
      <heading_deg>0</heading_deg>
    </spherical_coordinates>
    <state world_name='default'>
      <sim_time>1418 264000000</sim_time>
      <real_time>105 134342644</real_time>
      <wall_time>1551465804 496049454</wall_time>
      <iterations>76557</iterations>
      <model name='cafe'>
        <pose frame=''>0 0 0 0 -0 0</pose>
        <scale>1 1 1</scale>
        <link name='link'>
          <pose frame=''>0 0 0 0 -0 0</pose>
          <velocity>0 0 0 0 -0 0</velocity>
          <acceleration>0 0 0 0 -0 0</acceleration>
          <wrench>0 0 0 0 -0 0</wrench>
        </link>
      </model>
      <model name='prius'>
        <pose frame=''>-0.480018 -0.006986 0.323031 0 0.000236 0.033192</pose>
        <scale>1 1 1</scale>
        <link name='base_link'>
          <pose frame=''>-0.480018 -0.006986 0.323031 0 0.000236 0.033192</pose>
          <velocity>-0.000626 0.00225 -0.001883 0.000393 -0.011567 0.054453</velocity>
          <acceleration>5.09296 -1.18326 -0.001625 0.010669 0.01077 -0.525745</acceleration>
          <wrench>5.09296 -1.18326 -0.001625 0 -0 0</wrench>
        </link>
        <link name='chassis'>
          <pose frame=''>0.969184 0.041103 0.323613 4.5e-05 -0 1.60319</pose>
          <velocity>-0.003318 0.0006 -0.015324 0.00018 -0.00531 0.000384</velocity>
          <acceleration>-0.018976 0.002012 -0.000418 -0.000532 0.027556 -0.193891</acceleration>
          <wrench>-26.0356 2.76007 -0.574137 0 -0 0</wrench>
        </link>
        <link name='fl_axle'>
          <pose frame=''>2.3536 0.853366 0.623736 0.002348 -3.9e-05 1.60187</pose>
          <velocity>-0.00077 0.001101 -0.029448 -0.008603 -0.132127 -2.38275</velocity>
          <acceleration>8.71722 -0.233392 0.000859 1.48118 -0.36604 2.45698</acceleration>
          <wrench>8.71722 -0.233392 0.000859 0 -0 0</wrench>
        </link>
        <link name='fr_axle'>
          <pose frame=''>2.40327 -0.67983 0.623736 0.002561 -5e-05 1.60429</pose>
          <velocity>-0.008936 0.001179 -0.029457 0.009725 0.140452 2.46705</velocity>
          <acceleration>-9.11743 -0.12161 -0.002482 -2.69726 -1.32864 -2.30684</acceleration>
          <wrench>-9.11743 -0.12161 -0.002482 0 -0 0</wrench>
        </link>
        <link name='front_left_wheel'>
          <pose frame=''>2.3536 0.853366 0.623694 1.132 -2.7e-05 1.60187</pose>
          <velocity>-0.00067 0.001086 -0.024632 -0.003527 -0.240642 -2.38276</velocity>
          <acceleration>9.03937 -0.260424 -0.00212 2.66672 -0.911318 2.45267</acceleration>
          <wrench>99.4331 -2.86467 -0.023315 0 -0 0</wrench>
        </link>
        <link name='front_right_wheel'>
          <pose frame=''>2.40327 -0.67983 0.623694 0.736646 -3.8e-05 1.60429</pose>
          <velocity>-0.009162 0.001167 -0.02462 0.013456 -0.030148 2.46705</velocity>
          <acceleration>-9.4465 -0.140952 -0.005208 -2.44549 1.1452 0.841825</acceleration>
          <wrench>-103.912 -1.55047 -0.057292 0 -0 0</wrench>
        </link>
        <link name='rear_left_wheel'>
          <pose frame=''>-0.505708 0.786727 0.623684 -1.60965 3e-06 1.60319</pose>
          <velocity>-0.006022 -8.7e-05 -0.023713 0.000265 -0.019262 0.000387</velocity>
          <acceleration>0.074949 0.213109 0.009099 -1.18542 0.119774 -0.188944</acceleration>
          <wrench>0.824442 2.3442 0.100086 0 -0 0</wrench>
        </link>
        <link name='rear_right_wheel'>
          <pose frame=''>-0.454345 -0.79844 0.623684 -1.4431 2e-06 1.60319</pose>
          <velocity>-0.005349 -6.5e-05 -0.023687 0.000194 -0.017121 0.000386</velocity>
          <acceleration>-0.111578 0.207457 0.007828 -1.16415 -0.21944 -0.189196</acceleration>
          <wrench>-1.22736 2.28203 0.086112 0 -0 0</wrench>
        </link>
        <link name='steering_wheel'>
          <pose frame=''>1.58518 0.418985 1.31183 -1.30205 -0 1.60319</pose>
          <velocity>-0.008741 0.000659 -0.011902 0.000193 -0.005376 0.000384</velocity>
          <acceleration>0.056269 -0.113843 -0.004486 0.038094 0.008075 -0.174733</acceleration>
          <wrench>0.056269 -0.113843 -0.004486 0 -0 0</wrench>
        </link>
      </model>
      <light name='sun'>
        <pose frame=''>0.5 0 1 0 -0 0</pose>
      </light>
    </state>
    <gui fullscreen='0'>
      <camera name='user_camera'>
        <pose frame=''>164.478 -122.879 113.552 0 0.517796 2.38416</pose>
        <view_controller>orbit</view_controller>
        <projection_type>perspective</projection_type>
      </camera>
    </gui>
    <model name='prius'>
      <link name='base_link'>
        <pose frame=''>0 0 0 0 -0 0</pose>
        <inertial>
          <pose frame=''>0 0 0 0 -0 0</pose>
          <mass>1</mass>
          <inertia>
            <ixx>0.001</ixx>
            <ixy>0</ixy>
            <ixz>0</ixz>
            <iyy>0.001</iyy>
            <iyz>0</iyz>
            <izz>0.001</izz>
          </inertia>
        </inertial>
        <self_collide>0</self_collide>
        <enable_wind>0</enable_wind>
        <kinematic>0</kinematic>
      </link>
      <link name='chassis'>
        <pose frame=''>1.45 0 0 0 -0 1.57</pose>
        <inertial>
          <pose frame=''>-0 -0.00441 0.483098 0 -0 1.5708</pose>
          <mass>1372</mass>
          <inertia>
            <ixx>2591.33</ixx>
            <ixy>0.000203846</ixy>
            <ixz>-1.05374</ixz>
            <iyy>657</iyy>
            <iyz>3.87061e-06</iyz>
            <izz>2749.84</izz>
          </inertia>
        </inertial>
        <collision name='chassis_collision'>
          <pose frame=''>0 0.05 0.625 0 -0 0</pose>
          <geometry>
            <box>
              <size>1.7526 2.1 0.95</size>
            </box>
          </geometry>
          <max_contacts>10</max_contacts>
          <surface>
            <contact>
              <ode/>
            </contact>
            <bounce/>
            <friction>
              <torsional>
                <ode/>
              </torsional>
              <ode/>
            </friction>
          </surface>
        </collision>
        <collision name='chassis_fixed_joint_lump__front_bumper_collision_1'>
          <pose frame=''>0 -2 0.458488 0 -0 0</pose>
          <geometry>
            <box>
              <size>1.33728 0.48 0.566691</size>
            </box>
          </geometry>
          <max_contacts>10</max_contacts>
          <surface>
            <contact>
              <ode/>
            </contact>
            <bounce/>
            <friction>
              <torsional>
                <ode/>
              </torsional>
              <ode/>
            </friction>
          </surface>
        </collision>
        <collision name='chassis_fixed_joint_lump__hood_collision_2'>
          <pose frame=''>0 -1.90084 0.676305 0.341247 -0 0</pose>
          <geometry>
            <box>
              <size>1.59797 0.493107 0.265468</size>
            </box>
          </geometry>
          <max_contacts>10</max_contacts>
          <surface>
            <contact>
              <ode/>
            </contact>
            <bounce/>
            <friction>
              <torsional>
                <ode/>
              </torsional>
              <ode/>
            </friction>
          </surface>
        </collision>
        <collision name='chassis_fixed_joint_lump__windshield_collision_3'>
          <pose frame=''>0 -0.875105 1.03227 0.335476 -0 0</pose>
          <geometry>
            <box>
              <size>1.16838 1.65425 0.272347</size>
            </box>
          </geometry>
          <max_contacts>10</max_contacts>
          <surface>
            <contact>
              <ode/>
            </contact>
            <bounce/>
            <friction>
              <torsional>
                <ode/>
              </torsional>
              <ode/>
            </friction>
          </surface>
        </collision>
        <collision name='chassis_fixed_joint_lump__top_front_collision_4'>
          <pose frame=''>0 0.161236 1.38604 0.13503 -0 0</pose>
          <geometry>
            <box>
              <size>1.27915 0.625988 0.171868</size>
            </box>
          </geometry>
          <max_contacts>10</max_contacts>
          <surface>
            <contact>
              <ode/>
            </contact>
            <bounce/>
            <friction>
              <torsional>
                <ode/>
              </torsional>
              <ode/>
            </friction>
          </surface>
        </collision>
        <collision name='chassis_fixed_joint_lump__top_rear_collision_5'>
          <pose frame=''>0 0.817696 1.36007 -0.068997 0 0</pose>
          <geometry>
            <box>
              <size>1.28513 0.771189 0.226557</size>
            </box>
          </geometry>
          <max_contacts>10</max_contacts>
          <surface>
            <contact>
              <ode/>
            </contact>
            <bounce/>
            <friction>
              <torsional>
                <ode/>
              </torsional>
              <ode/>
            </friction>
          </surface>
        </collision>
        <collision name='chassis_fixed_joint_lump__rear_window_collision_6'>
          <pose frame=''>0 1.64053 1.17513 -0.262017 0 0</pose>
          <geometry>
            <box>
              <size>1.26785 1.11634 0.244286</size>
            </box>
          </geometry>
          <max_contacts>10</max_contacts>
          <surface>
            <contact>
              <ode/>
            </contact>
            <bounce/>
            <friction>
              <torsional>
                <ode/>
              </torsional>
              <ode/>
            </friction>
          </surface>
        </collision>
        <collision name='chassis_fixed_joint_lump__trunk_collision_7'>
          <pose frame=''>0 1.63706 0.88818 0 -0 0</pose>
          <geometry>
            <box>
              <size>1.78806 1.13899 0.482746</size>
            </box>
          </geometry>
          <max_contacts>10</max_contacts>
          <surface>
            <contact>
              <ode/>
            </contact>
            <bounce/>
            <friction>
              <torsional>
                <ode/>
              </torsional>
              <ode/>
            </friction>
          </surface>
        </collision>
        <collision name='chassis_fixed_joint_lump__back_bumper_collision_8'>
          <pose frame=''>0 2.05445 0.57787 0 -0 0</pose>
          <geometry>
            <box>
              <size>1.78165 0.512093 0.581427</size>
            </box>
          </geometry>
          <max_contacts>10</max_contacts>
          <surface>
            <contact>
              <ode/>
            </contact>
            <bounce/>
            <friction>
              <torsional>
                <ode/>
              </torsional>
              <ode/>
            </friction>
          </surface>
        </collision>
        <visual name='chassis_visual'>
          <pose frame=''>0 0 0 0 -0 0</pose>
          <geometry>
            <mesh>
              <scale>0.01 0.01 0.01</scale>
              <uri>/home/manthan/Path_tracking_git_ws/src/Path-Tracking-Simulation/car_demo/prius_description/meshes/hybrid_body.obj</uri>
            </mesh>
          </geometry>
        </visual>
        <velocity_decay/>
        <sensor name='back_camera_sensor' type='camera'>
          <update_rate>30</update_rate>
          <camera name='back_camera'>
            <horizontal_fov>1.39626</horizontal_fov>
            <image>
              <width>800</width>
              <height>800</height>
              <format>R8G8B8</format>
            </image>
            <clip>
              <near>0.02</near>
              <far>300</far>
            </clip>
            <noise>
              <type>gaussian</type>
              <mean>0</mean>
              <stddev>0.007</stddev>
            </noise>
          </camera>
          <plugin name='back_camera_controller' filename='libgazebo_ros_camera.so'>
            <alwaysOn>false</alwaysOn>
            <updateRate>0.0</updateRate>
            <cameraName>/prius/back_camera</cameraName>
            <imageTopicName>image_raw</imageTopicName>
            <cameraInfoTopicName>/prius/back_camera_info</cameraInfoTopicName>
            <frameName>camera_link</frameName>
            <hackBaseline>0.07</hackBaseline>
            <distortionK1>0.0</distortionK1>
            <distortionK2>0.0</distortionK2>
            <distortionK3>0.0</distortionK3>
            <distortionT1>0.0</distortionT1>
            <distortionT2>0.0</distortionT2>
            <robotNamespace>/</robotNamespace>
          </plugin>
          <pose frame=''>0 1.45 1.4 0 0.05 1.5707</pose>
        </sensor>
        <velocity_decay/>
        <sensor name='back_left_far_sonar_sensor' type='ray'>
          <ray>
            <scan>
              <horizontal>
                <samples>1</samples>
                <resolution>1</resolution>
                <min_angle>0</min_angle>
                <max_angle>0</max_angle>
              </horizontal>
              <vertical>
                <samples>1</samples>
                <min_angle>0</min_angle>
                <max_angle>0</max_angle>
              </vertical>
            </scan>
            <range>
              <min>0.2</min>
              <max>5</max>
              <resolution>0.1</resolution>
            </range>
          </ray>
          <plugin name='back_left_far_sonar_sensor' filename='libgazebo_ros_range.so'>
            <topicName>/prius/back_sonar/left_far_range</topicName>
            <frameName>back_left_far_sonar_link</frameName>
            <robotNamespace>/</robotNamespace>
          </plugin>
          <always_on>0</always_on>
          <update_rate>5</update_rate>
          <visualize>0</visualize>
          <pose frame=''>0.7 2.4 0.5 0 -0 1.5707</pose>
        </sensor>
        <velocity_decay/>
        <sensor name='back_left_middle_sonar_sensor' type='ray'>
          <ray>
            <scan>
              <horizontal>
                <samples>1</samples>
                <resolution>1</resolution>
                <min_angle>0</min_angle>
                <max_angle>0</max_angle>
              </horizontal>
              <vertical>
                <samples>1</samples>
                <min_angle>0</min_angle>
                <max_angle>0</max_angle>
              </vertical>
            </scan>
            <range>
              <min>0.2</min>
              <max>5</max>
              <resolution>0.1</resolution>
            </range>
          </ray>
          <plugin name='back_left_middle_sonar_sensor' filename='libgazebo_ros_range.so'>
            <topicName>/prius/back_sonar/left_middle_range</topicName>
            <frameName>back_left_middle_sonar_link</frameName>
            <robotNamespace>/</robotNamespace>
          </plugin>
          <always_on>0</always_on>
          <update_rate>5</update_rate>
          <visualize>0</visualize>
          <pose frame=''>0.24 2.4 0.5 0 -0 1.5707</pose>
        </sensor>
        <velocity_decay/>
        <sensor name='back_right_far_sonar_sensor' type='ray'>
          <ray>
            <scan>
              <horizontal>
                <samples>1</samples>
                <resolution>1</resolution>
                <min_angle>0</min_angle>
                <max_angle>0</max_angle>
              </horizontal>
              <vertical>
                <samples>1</samples>
                <min_angle>0</min_angle>
                <max_angle>0</max_angle>
              </vertical>
            </scan>
            <range>
              <min>0.2</min>
              <max>5</max>
              <resolution>0.1</resolution>
            </range>
          </ray>
          <plugin name='back_right_far_sonar_sensor' filename='libgazebo_ros_range.so'>
            <topicName>/prius/back_sonar/right_far_range</topicName>
            <frameName>back_right_far_sonar_link</frameName>
            <robotNamespace>/</robotNamespace>
          </plugin>
          <always_on>0</always_on>
          <update_rate>5</update_rate>
          <visualize>0</visualize>
          <pose frame=''>-0.7 2.4 0.5 0 -0 1.5707</pose>
        </sensor>
        <velocity_decay/>
        <sensor name='back_right_middle_sonar_sensor' type='ray'>
          <ray>
            <scan>
              <horizontal>
                <samples>1</samples>
                <resolution>1</resolution>
                <min_angle>0</min_angle>
                <max_angle>0</max_angle>
              </horizontal>
              <vertical>
                <samples>1</samples>
                <min_angle>0</min_angle>
                <max_angle>0</max_angle>
              </vertical>
            </scan>
            <range>
              <min>0.2</min>
              <max>5</max>
              <resolution>0.1</resolution>
            </range>
          </ray>
          <plugin name='back_right_middle_sonar_sensor' filename='libgazebo_ros_range.so'>
            <topicName>/prius/back_sonar/right_middle_range</topicName>
            <frameName>back_right_middle_sonar_link</frameName>
            <robotNamespace>/</robotNamespace>
          </plugin>
          <always_on>0</always_on>
          <update_rate>5</update_rate>
          <visualize>0</visualize>
          <pose frame=''>-0.24 2.4 0.5 0 -0 1.5707</pose>
        </sensor>
        <velocity_decay/>
        <sensor name='center_laser_sensor' type='ray'>
          <ray>
            <scan>
              <horizontal>
                <samples>512</samples>
                <resolution>1</resolution>
                <min_angle>-3.14</min_angle>
                <max_angle>3.14</max_angle>
              </horizontal>
              <vertical>
                <samples>16</samples>
                <min_angle>-0.1</min_angle>
                <max_angle>-0.35</max_angle>
              </vertical>
            </scan>
            <range>
              <min>0.2</min>
              <max>30</max>
              <resolution>0.01</resolution>
            </range>
          </ray>
          <plugin name='center_laser' filename='libgazebo_ros_block_laser.so'>
            <topicName>/prius/center_laser/scan</topicName>
            <frameName>center_laser_link</frameName>
            <robotNamespace>/</robotNamespace>
          </plugin>
          <always_on>1</always_on>
          <update_rate>30</update_rate>
          <visualize>0</visualize>
          <pose frame=''>0 0.4 1.8 0 0 -1.5707</pose>
        </sensor>
        <velocity_decay/>
        <sensor name='front_camera_sensor' type='camera'>
          <update_rate>30</update_rate>
          <camera name='front_camera'>
            <horizontal_fov>1.39626</horizontal_fov>
            <image>
              <width>800</width>
              <height>800</height>
              <format>R8G8B8</format>
            </image>
            <clip>
              <near>0.02</near>
              <far>300</far>
            </clip>
            <noise>
              <type>gaussian</type>
              <mean>0</mean>
              <stddev>0.007</stddev>
            </noise>
          </camera>
          <plugin name='front_camera_controller' filename='libgazebo_ros_camera.so'>
            <alwaysOn>false</alwaysOn>
            <updateRate>0.0</updateRate>
            <cameraName>/prius/front_camera</cameraName>
            <imageTopicName>image_raw</imageTopicName>
            <cameraInfoTopicName>/prius/front_camera_info</cameraInfoTopicName>
            <frameName>camera_link</frameName>
            <hackBaseline>0.07</hackBaseline>
            <distortionK1>0.0</distortionK1>
            <distortionK2>0.0</distortionK2>
            <distortionK3>0.0</distortionK3>
            <distortionT1>0.0</distortionT1>
            <distortionT2>0.0</distortionT2>
            <robotNamespace>/</robotNamespace>
          </plugin>
          <pose frame=''>0 -0.4 1.4 0 0.05 -1.5707</pose>
        </sensor>
        <velocity_decay/>
        <sensor name='front_left_far_sonar_sensor' type='ray'>
          <ray>
            <scan>
              <horizontal>
                <samples>1</samples>
                <resolution>1</resolution>
                <min_angle>0</min_angle>
                <max_angle>0</max_angle>
              </horizontal>
              <vertical>
                <samples>1</samples>
                <min_angle>0</min_angle>
                <max_angle>0</max_angle>
              </vertical>
            </scan>
            <range>
              <min>0.2</min>
              <max>5</max>
              <resolution>0.1</resolution>
            </range>
          </ray>
          <plugin name='front_left_far_sonar_sensor' filename='libgazebo_ros_range.so'>
            <topicName>/prius/front_sonar/left_far_range</topicName>
            <frameName>front_left_far_sonar_link</frameName>
            <robotNamespace>/</robotNamespace>
          </plugin>
          <always_on>0</always_on>
          <update_rate>5</update_rate>
          <visualize>0</visualize>
          <pose frame=''>0.7 -2.1 0.5 0 0 -1.5707</pose>
        </sensor>
        <velocity_decay/>
        <sensor name='front_left_laser_sensor' type='ray'>
          <ray>
            <scan>
              <horizontal>
                <samples>640</samples>
                <resolution>1</resolution>
                <min_angle>-2.26889</min_angle>
                <max_angle>2.2689</max_angle>
              </horizontal>
              <vertical>
                <samples>1</samples>
                <min_angle>0</min_angle>
                <max_angle>0</max_angle>
              </vertical>
            </scan>
            <range>
              <min>0.2</min>
              <max>30</max>
              <resolution>0.01</resolution>
            </range>
          </ray>
          <plugin name='front_left_laser' filename='libgazebo_ros_laser.so'>
            <topicName>/prius/front_left_laser/scan</topicName>
            <frameName>front_left_laser_link</frameName>
            <robotNamespace>/</robotNamespace>
          </plugin>
          <always_on>1</always_on>
          <update_rate>30</update_rate>
          <visualize>0</visualize>
          <pose frame=''>1 -2.3 0.5 0 0.05 -3.14</pose>
        </sensor>
        <velocity_decay/>
        <sensor name='front_left_middle_sonar_sensor' type='ray'>
          <ray>
            <scan>
              <horizontal>
                <samples>1</samples>
                <resolution>1</resolution>
                <min_angle>0</min_angle>
                <max_angle>0</max_angle>
              </horizontal>
              <vertical>
                <samples>1</samples>
                <min_angle>0</min_angle>
                <max_angle>0</max_angle>
              </vertical>
            </scan>
            <range>
              <min>0.2</min>
              <max>5</max>
              <resolution>0.1</resolution>
            </range>
          </ray>
          <plugin name='front_left_middle_sonar_sensor' filename='libgazebo_ros_range.so'>
            <topicName>/prius/front_sonar/left_middle_range</topicName>
            <frameName>front_left_middle_sonar_link</frameName>
            <robotNamespace>/</robotNamespace>
          </plugin>
          <always_on>0</always_on>
          <update_rate>5</update_rate>
          <visualize>0</visualize>
          <pose frame=''>0.24 -2.3 0.5 0 0 -1.5707</pose>
        </sensor>
        <velocity_decay/>
        <sensor name='front_right_far_sonar_sensor' type='ray'>
          <ray>
            <scan>
              <horizontal>
                <samples>1</samples>
                <resolution>1</resolution>
                <min_angle>0</min_angle>
                <max_angle>0</max_angle>
              </horizontal>
              <vertical>
                <samples>1</samples>
                <min_angle>0</min_angle>
                <max_angle>0</max_angle>
              </vertical>
            </scan>
            <range>
              <min>0.2</min>
              <max>5</max>
              <resolution>0.1</resolution>
            </range>
          </ray>
          <plugin name='front_right_far_sonar_sensor' filename='libgazebo_ros_range.so'>
            <topicName>/prius/front_sonar/right_far_range</topicName>
            <frameName>front_right_far_sonar_link</frameName>
            <robotNamespace>/</robotNamespace>
          </plugin>
          <always_on>0</always_on>
          <update_rate>5</update_rate>
          <visualize>0</visualize>
          <pose frame=''>-0.7 -2.1 0.5 0 0 -1.5707</pose>
        </sensor>
        <velocity_decay/>
        <sensor name='front_right_laser_sensor' type='ray'>
          <ray>
            <scan>
              <horizontal>
                <samples>640</samples>
                <resolution>1</resolution>
                <min_angle>-2.26889</min_angle>
                <max_angle>2.2689</max_angle>
              </horizontal>
              <vertical>
                <samples>1</samples>
                <min_angle>0</min_angle>
                <max_angle>0</max_angle>
              </vertical>
            </scan>
            <range>
              <min>0.2</min>
              <max>30</max>
              <resolution>0.01</resolution>
            </range>
          </ray>
          <plugin name='front_right_laser' filename='libgazebo_ros_laser.so'>
            <topicName>/prius/front_right_laser/scan</topicName>
            <frameName>front_right_laser_link</frameName>
            <robotNamespace>/</robotNamespace>
          </plugin>
          <always_on>1</always_on>
          <update_rate>30</update_rate>
          <visualize>0</visualize>
          <pose frame=''>-1 -2.3 0.5 -0 0.05 3.14</pose>
        </sensor>
        <velocity_decay/>
        <sensor name='front_right_middle_sonar_sensor' type='ray'>
          <ray>
            <scan>
              <horizontal>
                <samples>1</samples>
                <resolution>1</resolution>
                <min_angle>0</min_angle>
                <max_angle>0</max_angle>
              </horizontal>
              <vertical>
                <samples>1</samples>
                <min_angle>0</min_angle>
                <max_angle>0</max_angle>
              </vertical>
            </scan>
            <range>
              <min>0.2</min>
              <max>5</max>
              <resolution>0.1</resolution>
            </range>
          </ray>
          <plugin name='front_right_middle_sonar_sensor' filename='libgazebo_ros_range.so'>
            <topicName>/prius/front_sonar/right_middle_range</topicName>
            <frameName>front_right_middle_sonar_link</frameName>
            <robotNamespace>/</robotNamespace>
          </plugin>
          <always_on>0</always_on>
          <update_rate>5</update_rate>
          <visualize>0</visualize>
          <pose frame=''>-0.24 -2.3 0.5 0 0 -1.5707</pose>
        </sensor>
        <velocity_decay/>
        <sensor name='left_camera_sensor' type='camera'>
          <update_rate>30</update_rate>
          <camera name='left_camera'>
            <horizontal_fov>1.39626</horizontal_fov>
            <image>
              <width>800</width>
              <height>800</height>
              <format>R8G8B8</format>
            </image>
            <clip>
              <near>0.02</near>
              <far>300</far>
            </clip>
            <noise>
              <type>gaussian</type>
              <mean>0</mean>
              <stddev>0.007</stddev>
            </noise>
          </camera>
          <plugin name='left_camera_controller' filename='libgazebo_ros_camera.so'>
            <alwaysOn>false</alwaysOn>
            <updateRate>0.0</updateRate>
            <cameraName>/prius/left_camera</cameraName>
            <imageTopicName>image_raw</imageTopicName>
            <cameraInfoTopicName>/prius/left_camera_info</cameraInfoTopicName>
            <frameName>camera_link</frameName>
            <hackBaseline>0.07</hackBaseline>
            <distortionK1>0.0</distortionK1>
            <distortionK2>0.0</distortionK2>
            <distortionK3>0.0</distortionK3>
            <distortionT1>0.0</distortionT1>
            <distortionT2>0.0</distortionT2>
            <robotNamespace>/</robotNamespace>
          </plugin>
          <pose frame=''>1 -0.7 1 0 0.05 1</pose>
        </sensor>
        <velocity_decay/>
        <sensor name='main_laser_sensor' type='ray'>
          <ray>
            <scan>
              <horizontal>
                <samples>640</samples>
                <resolution>1</resolution>
                <min_angle>-1.4</min_angle>
                <max_angle>1.4</max_angle>
              </horizontal>
              <vertical>
                <samples>1</samples>
                <min_angle>0</min_angle>
                <max_angle>0</max_angle>
              </vertical>
            </scan>
            <range>
              <min>0.2</min>
              <max>30</max>
              <resolution>0.01</resolution>
            </range>
          </ray>
          <plugin name='main_laser' filename='libgazebo_ros_laser.so'>
            <topicName>/prius/main_laser/scan</topicName>
            <frameName>main_laser_link</frameName>
            <robotNamespace>/</robotNamespace>
          </plugin>
          <always_on>1</always_on>
          <update_rate>30</update_rate>
          <visualize>0</visualize>
          <pose frame=''>0 -2.3 0.33 0 0 -1.57</pose>
        </sensor>
        <gravity>1</gravity>
        <velocity_decay/>
        <sensor name='right_camera_sensor' type='camera'>
          <update_rate>30</update_rate>
          <camera name='right_camera'>
            <horizontal_fov>1.39626</horizontal_fov>
            <image>
              <width>800</width>
              <height>800</height>
              <format>R8G8B8</format>
            </image>
            <clip>
              <near>0.02</near>
              <far>300</far>
            </clip>
            <noise>
              <type>gaussian</type>
              <mean>0</mean>
              <stddev>0.007</stddev>
            </noise>
          </camera>
          <plugin name='right_camera_controller' filename='libgazebo_ros_camera.so'>
            <alwaysOn>false</alwaysOn>
            <updateRate>0.0</updateRate>
            <cameraName>/prius/right_camera</cameraName>
            <imageTopicName>image_raw</imageTopicName>
            <cameraInfoTopicName>/prius/right_camera_info</cameraInfoTopicName>
            <frameName>camera_link</frameName>
            <hackBaseline>0.07</hackBaseline>
            <distortionK1>0.0</distortionK1>
            <distortionK2>0.0</distortionK2>
            <distortionK3>0.0</distortionK3>
            <distortionT1>0.0</distortionT1>
            <distortionT2>0.0</distortionT2>
            <robotNamespace>/</robotNamespace>
          </plugin>
          <pose frame=''>-1 -0.7 1 0 0.05 2.1416</pose>
        </sensor>
        <self_collide>0</self_collide>
        <enable_wind>0</enable_wind>
        <kinematic>0</kinematic>
      </link>
      <joint name='base_link_connection' type='revolute'>
        <child>chassis</child>
        <parent>base_link</parent>
        <axis>
          <limit>
            <lower>0</lower>
            <upper>0</upper>
          </limit>
          <dynamics>
            <damping>0</damping>
            <friction>0</friction>
            <spring_reference>0</spring_reference>
            <spring_stiffness>0</spring_stiffness>
          </dynamics>
          <use_parent_model_frame>1</use_parent_model_frame>
          <xyz>0 0 1</xyz>
        </axis>
        <physics>
          <ode>
            <limit>
              <cfm>0</cfm>
              <erp>0.2</erp>
            </limit>
          </ode>
        </physics>
      </joint>
      <link name='fl_axle'>
        <pose frame=''>2.86061 0.765877 0.3 0 -0 1.57</pose>
        <inertial>
          <pose frame=''>0 0 0 0 -0 0</pose>
          <mass>1</mass>
          <inertia>
            <ixx>0.004</ixx>
            <ixy>0</ixy>
            <ixz>0</ixz>
            <iyy>0.004</iyy>
            <iyz>0</iyz>
            <izz>0.004</izz>
          </inertia>
        </inertial>
        <self_collide>0</self_collide>
        <enable_wind>0</enable_wind>
        <kinematic>0</kinematic>
      </link>
      <joint name='front_left_steer_joint' type='revolute'>
        <child>fl_axle</child>
        <parent>chassis</parent>
        <axis>
          <xyz>0 0 1</xyz>
          <limit>
            <lower>-1e+16</lower>
            <upper>1e+16</upper>
          </limit>
          <dynamics>
            <spring_reference>0</spring_reference>
            <spring_stiffness>0</spring_stiffness>
          </dynamics>
          <use_parent_model_frame>1</use_parent_model_frame>
        </axis>
      </joint>
      <link name='front_left_wheel'>
        <pose frame=''>2.86061 0.765877 0.3 0 -0 1.57</pose>
        <inertial>
          <pose frame=''>0 0 0 0 -0 0</pose>
          <mass>11</mass>
          <inertia>
            <ixx>0.586312</ixx>
            <ixy>0</ixy>
            <ixz>0</ixz>
            <iyy>0.335529</iyy>
            <iyz>0</iyz>
            <izz>0.335529</izz>
          </inertia>
        </inertial>
        <collision name='front_left_wheel_collision_collision'>
          <pose frame=''>0 0 0 0 -0 0</pose>
          <geometry>
            <sphere>
              <radius>0.31265</radius>
            </sphere>
          </geometry>
          <surface>
            <contact>
              <ode>
                <kp>1e+08</kp>
                <min_depth>0.005</min_depth>
              </ode>
            </contact>
            <friction>
              <ode>
                <mu>0.9</mu>
                <mu2>0.9</mu2>
              </ode>
              <torsional>
                <ode/>
              </torsional>
            </friction>
            <bounce/>
          </surface>
          <max_contacts>10</max_contacts>
        </collision>
        <visual name='front_left_wheel_visual'>
          <pose frame=''>0 0 0 0 -0 0</pose>
          <geometry>
            <mesh>
              <scale>0.01 0.01 0.01</scale>
              <uri>/home/manthan/Path_tracking_git_ws/src/Path-Tracking-Simulation/car_demo/prius_description/meshes/wheel.obj</uri>
            </mesh>
          </geometry>
          <material>
            <script>
              <uri>__default__</uri>
              <name>__default__</name>
            </script>
          </material>
        </visual>
        <gravity>1</gravity>
        <velocity_decay/>
        <self_collide>0</self_collide>
        <enable_wind>0</enable_wind>
        <kinematic>0</kinematic>
      </link>
      <joint name='front_left_wheel_joint' type='revolute'>
        <child>front_left_wheel</child>
        <parent>fl_axle</parent>
        <axis>
          <xyz>0.000796 1 0</xyz>
          <limit>
            <lower>-1e+16</lower>
            <upper>1e+16</upper>
          </limit>
          <dynamics>
            <spring_reference>0</spring_reference>
            <spring_stiffness>0</spring_stiffness>
          </dynamics>
          <use_parent_model_frame>1</use_parent_model_frame>
        </axis>
      </joint>
      <link name='fr_axle'>
        <pose frame=''>2.85939 -0.768123 0.3 0 -0 1.57</pose>
        <inertial>
          <pose frame=''>0 0 0 0 -0 0</pose>
          <mass>1</mass>
          <inertia>
            <ixx>0.004</ixx>
            <ixy>0</ixy>
            <ixz>0</ixz>
            <iyy>0.004</iyy>
            <iyz>0</iyz>
            <izz>0.004</izz>
          </inertia>
        </inertial>
        <self_collide>0</self_collide>
        <enable_wind>0</enable_wind>
        <kinematic>0</kinematic>
      </link>
      <joint name='front_right_steer_joint' type='revolute'>
        <child>fr_axle</child>
        <parent>chassis</parent>
        <axis>
          <xyz>0 0 1</xyz>
          <limit>
            <lower>-1e+16</lower>
            <upper>1e+16</upper>
          </limit>
          <dynamics>
            <spring_reference>0</spring_reference>
            <spring_stiffness>0</spring_stiffness>
          </dynamics>
          <use_parent_model_frame>1</use_parent_model_frame>
        </axis>
      </joint>
      <link name='front_right_wheel'>
        <pose frame=''>2.85939 -0.768123 0.3 0 -0 1.57</pose>
        <inertial>
          <pose frame=''>0 0 0 0 -0 0</pose>
          <mass>11</mass>
          <inertia>
            <ixx>0.586312</ixx>
            <ixy>0</ixy>
            <ixz>0</ixz>
            <iyy>0.335529</iyy>
            <iyz>0</iyz>
            <izz>0.335529</izz>
          </inertia>
        </inertial>
        <collision name='front_right_wheel_collision_collision'>
          <pose frame=''>0 0 0 0 -0 0</pose>
          <geometry>
            <sphere>
              <radius>0.31265</radius>
            </sphere>
          </geometry>
          <surface>
            <contact>
              <ode>
                <kp>1e+08</kp>
                <min_depth>0.005</min_depth>
              </ode>
            </contact>
            <friction>
              <ode>
                <mu>0.9</mu>
                <mu2>0.9</mu2>
              </ode>
              <torsional>
                <ode/>
              </torsional>
            </friction>
            <bounce/>
          </surface>
          <max_contacts>10</max_contacts>
        </collision>
        <visual name='front_right_wheel_visual'>
          <pose frame=''>0 0 0 0 -0 0</pose>
          <geometry>
            <mesh>
              <scale>0.01 0.01 0.01</scale>
              <uri>/home/manthan/Path_tracking_git_ws/src/Path-Tracking-Simulation/car_demo/prius_description/meshes/wheel.obj</uri>
            </mesh>
          </geometry>
          <material>
            <script>
              <uri>__default__</uri>
              <name>__default__</name>
            </script>
          </material>
        </visual>
        <gravity>1</gravity>
        <velocity_decay/>
        <self_collide>0</self_collide>
        <enable_wind>0</enable_wind>
        <kinematic>0</kinematic>
      </link>
      <joint name='front_right_wheel_joint' type='revolute'>
        <child>front_right_wheel</child>
        <parent>fr_axle</parent>
        <axis>
          <xyz>0.000796 1 0</xyz>
          <limit>
            <lower>-1e+16</lower>
            <upper>1e+16</upper>
          </limit>
          <dynamics>
            <spring_reference>0</spring_reference>
            <spring_stiffness>0</spring_stiffness>
          </dynamics>
          <use_parent_model_frame>1</use_parent_model_frame>
        </axis>
      </joint>
      <link name='rear_left_wheel'>
        <pose frame=''>0.000632 0.794154 0.3 0 -0 1.57</pose>
        <inertial>
          <pose frame=''>0 0 0 0 -0 0</pose>
          <mass>11</mass>
          <inertia>
            <ixx>0.586312</ixx>
            <ixy>0</ixy>
            <ixz>0</ixz>
            <iyy>0.335529</iyy>
            <iyz>0</iyz>
            <izz>0.335529</izz>
          </inertia>
        </inertial>
        <collision name='rear_left_wheel_collision_collision'>
          <pose frame=''>0 0 0 0 -0 0</pose>
          <geometry>
            <sphere>
              <radius>0.31265</radius>
            </sphere>
          </geometry>
          <surface>
            <contact>
              <ode>
                <kp>1e+08</kp>
                <min_depth>0.005</min_depth>
              </ode>
            </contact>
            <friction>
              <ode>
                <mu>0.9</mu>
                <mu2>0.9</mu2>
              </ode>
              <torsional>
                <ode/>
              </torsional>
            </friction>
            <bounce/>
          </surface>
          <max_contacts>10</max_contacts>
        </collision>
        <visual name='rear_left_wheel_visual'>
          <pose frame=''>0 0 0 0 -0 0</pose>
          <geometry>
            <mesh>
              <scale>0.01 0.01 0.01</scale>
              <uri>/home/manthan/Path_tracking_git_ws/src/Path-Tracking-Simulation/car_demo/prius_description/meshes/wheel.obj</uri>
            </mesh>
          </geometry>
          <material>
            <script>
              <uri>__default__</uri>
              <name>__default__</name>
            </script>
          </material>
        </visual>
        <gravity>1</gravity>
        <velocity_decay/>
        <self_collide>0</self_collide>
        <enable_wind>0</enable_wind>
        <kinematic>0</kinematic>
      </link>
      <joint name='rear_left_wheel_joint' type='revolute'>
        <child>rear_left_wheel</child>
        <parent>chassis</parent>
        <axis>
          <xyz>0.000796 1 0</xyz>
          <limit>
            <lower>-1e+16</lower>
            <upper>1e+16</upper>
          </limit>
          <dynamics>
            <spring_reference>0</spring_reference>
            <spring_stiffness>0</spring_stiffness>
          </dynamics>
          <use_parent_model_frame>1</use_parent_model_frame>
        </axis>
      </joint>
      <link name='rear_right_wheel'>
        <pose frame=''>-0.000631 -0.791845 0.3 0 -0 1.57</pose>
        <inertial>
          <pose frame=''>0 0 0 0 -0 0</pose>
          <mass>11</mass>
          <inertia>
            <ixx>0.586312</ixx>
            <ixy>0</ixy>
            <ixz>0</ixz>
            <iyy>0.335529</iyy>
            <iyz>0</iyz>
            <izz>0.335529</izz>
          </inertia>
        </inertial>
        <collision name='rear_right_wheel_collision_collision'>
          <pose frame=''>0 0 0 0 -0 0</pose>
          <geometry>
            <sphere>
              <radius>0.31265</radius>
            </sphere>
          </geometry>
          <surface>
            <contact>
              <ode>
                <kp>1e+08</kp>
                <min_depth>0.005</min_depth>
              </ode>
            </contact>
            <friction>
              <ode>
                <mu>0.9</mu>
                <mu2>0.9</mu2>
              </ode>
              <torsional>
                <ode/>
              </torsional>
            </friction>
            <bounce/>
          </surface>
          <max_contacts>10</max_contacts>
        </collision>
        <visual name='rear_right_wheel_visual'>
          <pose frame=''>0 0 0 0 -0 0</pose>
          <geometry>
            <mesh>
              <scale>0.01 0.01 0.01</scale>
              <uri>/home/manthan/Path_tracking_git_ws/src/Path-Tracking-Simulation/car_demo/prius_description/meshes/wheel.obj</uri>
            </mesh>
          </geometry>
          <material>
            <script>
              <uri>__default__</uri>
              <name>__default__</name>
            </script>
          </material>
        </visual>
        <gravity>1</gravity>
        <velocity_decay/>
        <self_collide>0</self_collide>
        <enable_wind>0</enable_wind>
        <kinematic>0</kinematic>
      </link>
      <joint name='rear_right_wheel_joint' type='revolute'>
        <child>rear_right_wheel</child>
        <parent>chassis</parent>
        <axis>
          <xyz>0.000796 1 0</xyz>
          <limit>
            <lower>-1e+16</lower>
            <upper>1e+16</upper>
          </limit>
          <dynamics>
            <spring_reference>0</spring_reference>
            <spring_stiffness>0</spring_stiffness>
          </dynamics>
          <use_parent_model_frame>1</use_parent_model_frame>
        </axis>
      </joint>
      <link name='steering_wheel'>
        <pose frame=''>2.07815 0.357234 0.988243 -1.3021 0 1.57</pose>
        <inertial>
          <pose frame=''>0 0 0 0 -0 0</pose>
          <mass>1</mass>
          <inertia>
            <ixx>0.145833</ixx>
            <ixy>0</ixy>
            <ixz>0</ixz>
            <iyy>0.145833</iyy>
            <iyz>0</iyz>
            <izz>0.125</izz>
          </inertia>
        </inertial>
        <visual name='steering_wheel_visual'>
          <pose frame=''>0 0 0 1.3021 -0 0</pose>
          <geometry>
            <mesh>
              <scale>0.01 0.01 0.01</scale>
              <uri>/home/manthan/Path_tracking_git_ws/src/Path-Tracking-Simulation/car_demo/prius_description/meshes/steering_wheel.obj</uri>
            </mesh>
          </geometry>
        </visual>
        <self_collide>0</self_collide>
        <enable_wind>0</enable_wind>
        <kinematic>0</kinematic>
      </link>
      <joint name='steering_joint' type='revolute'>
        <child>steering_wheel</child>
        <parent>chassis</parent>
        <axis>
          <xyz>-0.964118 0.000768 0.265474</xyz>
          <limit>
            <lower>-1e+16</lower>
            <upper>1e+16</upper>
          </limit>
          <dynamics>
            <spring_reference>0</spring_reference>
            <spring_stiffness>0</spring_stiffness>
          </dynamics>
          <use_parent_model_frame>1</use_parent_model_frame>
        </axis>
      </joint>
      <plugin name='pruis_hybrid_drive' filename='libPriusHybridPlugin.so'>
        <chassis>chassis</chassis>
        <front_left_wheel>front_left_wheel_joint</front_left_wheel>
        <front_right_wheel>front_right_wheel_joint</front_right_wheel>
        <front_left_wheel_steering>front_left_steer_joint</front_left_wheel_steering>
        <front_right_wheel_steering>front_right_steer_joint</front_right_wheel_steering>
        <back_left_wheel>rear_left_wheel_joint</back_left_wheel>
        <back_right_wheel>rear_right_wheel_joint</back_right_wheel>
        <steering_wheel>steering_joint</steering_wheel>
        <chassis_aero_force_gain>0.63045</chassis_aero_force_gain>
        <front_torque>859.4004393000001</front_torque>
        <back_torque>0</back_torque>
        <front_brake_torque>1031.28052716</front_brake_torque>
        <back_brake_torque>687.5203514400001</back_brake_torque>
        <max_speed>37.998337013956565</max_speed>
        <min_gas_flow>8.981854013171626e-05</min_gas_flow>
        <gas_efficiency>0.371</gas_efficiency>
        <battery_charge_watt_hours>291</battery_charge_watt_hours>
        <battery_discharge_watt_hours>214</battery_discharge_watt_hours>
        <max_steer>0.6458</max_steer>
        <flwheel_steering_p_gain>1e4</flwheel_steering_p_gain>
        <frwheel_steering_p_gain>1e4</frwheel_steering_p_gain>
        <flwheel_steering_i_gain>0</flwheel_steering_i_gain>
        <frwheel_steering_i_gain>0</frwheel_steering_i_gain>
        <flwheel_steering_d_gain>3e2</flwheel_steering_d_gain>
        <frwheel_steering_d_gain>3e2</frwheel_steering_d_gain>
        <robotNamespace>/</robotNamespace>
      </plugin>
      <plugin name='joint_state_publisher' filename='libgazebo_ros_joint_state_publisher.so'>
        <jointName>rear_right_wheel_joint, rear_left_wheel_joint, front_right_wheel_joint, front_left_wheel_joint, front_right_steer_joint, front_left_steer_joint, steering_joint</jointName>
        <updateRate>100.0</updateRate>
        <alwaysOn>true</alwaysOn>
        <robotNamespace>/</robotNamespace>
      </plugin>
      <static>0</static>
      <plugin name='p3d' filename='libgazebo_ros_p3d.so'>
        <bodyName>base_link</bodyName>
        <topicName>base_pose_ground_truth</topicName>
        <frameName>map</frameName>
        <updateRate>100.0</updateRate>
        <robotNamespace>/</robotNamespace>
      </plugin>
      <pose frame=''>0 0 0.5 0 -0 0</pose>
    </model>
  </world>
</sdf>
